<?xml version="1.0"?>
<robot name="scara_robot">
    <material name="blue">
        <color rgba="0.0 0.0 1.0 1.0"/>
    </material>
    <material name="black">
        <color rgba="0.0 0.0 0.0 1.0"/>
    </material>
    <material name="white">
        <color rgba="1.0 1.0 1.0 1.0"/>
    </material>
    <material name="yellow">
        <color rgba="1.0 1.0 0.0 1.0"/>
    </material>


    <link name="base_link">
        <visual>
            <origin xyz="0.0 0.0 0.1" rpy="0.0 0.0 0.0"/>
            <geometry>
                <cylinder length="0.2" radius="0.1"/>
            </geometry>
            <material name="black"/>
        </visual>
    </link>
    <link name="arm1">
        <visual>
            <origin xyz="0.0 -0.5 0.0" rpy="0.0 0.0 0.0"/>
            <geometry>
                <box size="0.05 1.0 0.05"/>
            </geometry>
            <material name="white"/>
        </visual>
        <collision>
            <origin xyz="0.0 -0.5 0.0" rpy="0.0 0.0 0.0"/>
            <geometry>
                <box size="0.05 1.0 0.05"/>
            </geometry>
        </collision>

        <inertial>   
            <mass value=".2" />
            <inertia ixx="0.4" ixy="0.0" ixz="0.0" iyy="0.4" iyz="0.0" izz="0.2"/>  
        </inertial>
    </link>
    <joint name="arm1_joint" type="continuous">
        <origin xyz="0.0 0.0 0.1" rpy="0.0 0.0 0.0"/>
        <parent link="base_link"/>
        <child link="arm1"/>
        <axis xyz="0.0 0.0 1.0"/>
        <limit effort="100" lower="-100" upper="100" velocity="10"/>\
    </joint>

    <link name="arm2">
        <visual>
            <origin xyz="0.0 -0.4 0.0" rpy="0.0 0.0 0.0"/>
            <geometry>
                <box size="0.05 0.8 0.05"/>
            </geometry>
            <material name="blue"/>
        </visual>
        <collision>
            <origin xyz="0.0 -0.4 0.0" rpy="0.0 0.0 0.0"/>
            <geometry>
                <box size="0.05 0.8 0.05"/>
            </geometry>
        </collision>

        <inertial>   
            <mass value=".2" />
            <inertia ixx="0.4" ixy="0.0" ixz="0.0" iyy="0.4" iyz="0.0" izz="0.2"/>  
        </inertial>
    </link>
    <joint name="arm2_joint" type="continuous">
        <origin xyz="0.0 -1.0 0.0" rpy="0.0 0.0 0.0"/>
        <parent link="arm1"/>
        <child link="arm2"/>
        <axis xyz="0.0 0.0 1.0"/>
        <limit effort="100" lower="-100" upper="100" velocity="10"/>\
    </joint>



    <link name="arm3">
        <visual>
            <origin xyz="0.0 -0.35 0.0" rpy="0.0 0.0 0.0"/>
            <geometry>
                <box size="0.05 0.7 0.05"/>
            </geometry>
            <material name="yellow"/>
        </visual>
        <collision>
            <origin xyz="0.0 -0.35 0.0" rpy="0.0 0.0 0.0"/>
            <geometry>
                <box size="0.05 0.7 0.05"/>
            </geometry>
        </collision>

        <inertial>   
            <mass value=".2" />
            <inertia ixx="0.4" ixy="0.0" ixz="0.0" iyy="0.4" iyz="0.0" izz="0.2"/>  
        </inertial>
    </link>
    <joint name="arm3_joint" type="continuous">
        <origin xyz="0.0 -0.8 0.0" rpy="0.0 0.0 0.0"/>
        <parent link="arm2"/>
        <child link="arm3"/>
        <axis xyz="0.0 0.0 1.0"/>
        <limit effort="100" lower="-100" upper="100" velocity="10"/>\
    </joint>




    <link name="ee_link">
        <visual>
            <origin xyz="0.0 0.0 0.0" rpy="0.0 0.0 0.0"/>
            <geometry>
                <box size="0.1 0.1 0.1"/>
            </geometry>
            <material name="blue"/>
        </visual>
        <collision>
            <origin xyz="0.0 0.0 0.0" rpy="0.0 0.0 0.0"/>
            <geometry>
                <box size="0.1 0.1 0.1"/>
            </geometry>
        </collision>

        <inertial>   
            <mass value="0.1" />
            <inertia ixx="0.0" ixy="0.0" ixz="0.0" iyy="0.0" iyz="0.0" izz="0.0"/>  
        </inertial>
    </link>
    <joint name="ee_joint" type="fixed">
        <origin xyz="0.0 -0.7 0.0" rpy="0.0 0.0 0.0"/>
        <parent link="arm3"/>
        <child link="ee_link"/>
        <axis xyz="0.0 0.0 1.0"/>
    </joint>
</robot>